<?xml version="1.0" encoding="utf-8"?>
<robot
  name="elf2">
  <link
    name="base_link">
    <inertial>
      <origin
        xyz="-0.002719 0.001928 0.003917"
        rpy="0 0 0" />
      <mass
        value="8.948443" />
      <inertia
        ixx="0.18746"
        ixy="-0.000182"
        ixz="-0.001384"
        iyy="0.142272"
        iyz="0.000105"
        izz="0.069523" />
    </inertial>
    <visual>
      <origin
        xyz="0 0 0"
        rpy="0 0 0" />
      <geometry>
        <mesh
          filename="../meshes/base_link.STL" />
      </geometry>
      <material
        name="">
        <color
          rgba="0.75294 0.75294 0.75294 1" />
      </material>
    </visual>
    <collision>
      <origin
        xyz="0 0 0"
        rpy="0 0 0" />
      <geometry>
        <mesh
          filename="../meshes/base_link.STL" />
      </geometry>
    </collision>
  </link>
  <link
    name="l_shld_y_link">
    <inertial>
      <origin
        xyz="0.00068297 -0.00449372 2.22e-06"
        rpy="0 0 0" />
      <mass
        value="0.53804971" />
      <inertia
        ixx="0.00030648"
        ixy="4.03e-06"
        ixz="2e-08"
        iyy="0.00029153"
        iyz="1e-07"
        izz="0.00032312" />
    </inertial>
    <visual>
      <origin
        xyz="0 0 0"
        rpy="0 0 0" />
      <geometry>
        <mesh
          filename="../meshes/l_shld_y_link.STL" />
      </geometry>
      <material
        name="">
        <color
          rgba="0.752941176470588 0.752941176470588 0.752941176470588 1" />
      </material>
    </visual>
    <collision>
      <origin
        xyz="0 0 0"
        rpy="0 0 0" />
      <geometry>
        <mesh
          filename="../meshes/l_shld_y_link.STL" />
      </geometry>
    </collision>
  </link>
  <joint
    name="l_shld_y_joint"
    type="revolute">
    <origin
      xyz="0 0.21705 0.09205"
      rpy="0 0 0" />
    <parent
      link="base_link" />
    <child
      link="l_shld_y_link" />
    <axis
      xyz="0 1 0" />
    <limit
      lower="-2"
      upper="2"
      effort="27"
      velocity="20" />
  </joint>
  <link
    name="l_shld_x_link">
    <inertial>
      <origin
        xyz="-2.047e-05 5.316e-05 -0.06162654"
        rpy="0 0 0" />
      <mass
        value="0.48847489" />
      <inertia
        ixx="0.00027194"
        ixy="4e-08"
        ixz="-5.4e-07"
        iyy="0.00033709"
        iyz="-5.4e-07"
        izz="0.0002884" />
    </inertial>
    <visual>
      <origin
        xyz="0 0 0"
        rpy="0 0 0" />
      <geometry>
        <mesh
          filename="../meshes/l_shld_x_link.STL" />
      </geometry>
      <material
        name="">
        <color
          rgba="0.752941176470588 0.752941176470588 0.752941176470588 1" />
      </material>
    </visual>
    <collision>
      <origin
        xyz="0 0 0"
        rpy="0 0 0" />
      <geometry>
        <mesh
          filename="../meshes/l_shld_x_link.STL" />
      </geometry>
    </collision>
  </link>
  <joint
    name="l_shld_x_joint"
    type="revolute">
    <origin
      xyz="0 0 0"
      rpy="0 0 0" />
    <parent
      link="l_shld_y_link" />
    <child
      link="l_shld_x_link" />
    <axis
      xyz="1 0 0" />
    <limit
      lower="-0.5"
      upper="1.57"
      effort="27"
      velocity="20" />
  </joint>
  <link
    name="l_shld_z_link">
    <inertial>
      <origin
        xyz="4.164e-05 0.00022669 -0.2212782"
        rpy="0 0 0" />
      <mass
        value="0.59309528" />
      <inertia
        ixx="0.00136573"
        ixy="5.3e-07"
        ixz="-1e-08"
        iyy="0.00133989"
        iyz="1.22e-06"
        izz="0.00030342" />
    </inertial>
    <visual>
      <origin
        xyz="0 0 0"
        rpy="0 0 0" />
      <geometry>
        <mesh
          filename="../meshes/l_shld_z_link.STL" />
      </geometry>
      <material
        name="">
        <color
          rgba="0.752941176470588 0.752941176470588 0.752941176470588 1" />
      </material>
    </visual>
    <collision>
      <origin
        xyz="0 0 0"
        rpy="0 0 0" />
      <geometry>
        <mesh
          filename="../meshes/l_shld_z_link.STL" />
      </geometry>
    </collision>
  </link>
  <joint
    name="l_shld_z_joint"
    type="revolute">
    <origin
      xyz="0 0 0"
      rpy="0 0 0" />
    <parent
      link="l_shld_x_link" />
    <child
      link="l_shld_z_link" />
    <axis
      xyz="0 0 1" />
    <limit
      lower="-1.57"
      upper="1.57"
      effort="7"
      velocity="20" />
  </joint>
  <link
    name="l_elb_y_link">
    <inertial>
      <origin
        xyz="5.192e-05 1.999e-05 -0.08561189"
        rpy="0 0 0" />
      <mass
        value="0.50005725" />
      <inertia
        ixx="0.00043713"
        ixy="-4e-08"
        ixz="-4.9e-07"
        iyy="0.00036043"
        iyz="6.3e-07"
        izz="0.00030266" />
    </inertial>
    <visual>
      <origin
        xyz="0 0 0"
        rpy="0 0 0" />
      <geometry>
        <mesh
          filename="../meshes/l_elb_y_link.STL" />
      </geometry>
      <material
        name="">
        <color
          rgba="0.752941176470588 0.752941176470588 0.752941176470588 1" />
      </material>
    </visual>
    <collision>
      <origin
        xyz="0 0 0"
        rpy="0 0 0" />
      <geometry>
        <mesh
          filename="../meshes/l_elb_y_link.STL" />
      </geometry>
    </collision>
  </link>
  <joint
    name="l_elb_y_joint"
    type="revolute">
    <origin
      xyz="0 0 -0.24"
      rpy="0 0 0" />
    <parent
      link="l_shld_z_link" />
    <child
      link="l_elb_y_link" />
    <axis
      xyz="0 1 0" />
    <limit
      lower="-2.355"
      upper="0.5"
      effort="27"
      velocity="20" />
  </joint>
  <link
    name="l_elb_z_link">
    <inertial>
      <origin
        xyz="0 0 0"
        rpy="0 0 0" />
      <mass
        value="0.13457416" />
      <inertia
        ixx="0.00040001"
        ixy="-0.0"
        ixz="-2e-08"
        iyy="0.00039996"
        iyz="1.5e-07"
        izz="5.662e-05" />
    </inertial>
    <visual>
      <origin
        xyz="0 0 0"
        rpy="3.1415926 0 1.5707963" />
      <geometry>
        <mesh
          filename="../meshes/elb_z_link.STL" />
      </geometry>
      <material
        name="">
        <color
          rgba="0.752941176470588 0.752941176470588 0.752941176470588 1" />
      </material>
    </visual>
    <collision>
      <origin
        xyz="0 0 0"
        rpy="3.1415926 0 1.5707963" />
      <geometry>
        <mesh
          filename="../meshes/elb_z_link.STL" />
      </geometry>
    </collision>
  </link>
  <joint
    name="l_elb_z_joint"
    type="revolute">
    <origin
      xyz="0 0 -0.12"
      rpy="0 0 0" />
    <parent
      link="l_elb_y_link" />
    <child
      link="l_elb_z_link" />
    <axis
      xyz="0 0 1" />
    <limit
      lower="-0.785"
      upper="0.785"
      effort="7"
      velocity="20" />
  </joint>
  <link
    name="l_wrist_y_link">
    <inertial>
      <origin
        xyz="0 0 0"
        rpy="0 0 0" />
      <mass
        value="0.13457416" />
      <inertia
        ixx="0.00040001"
        ixy="-0.0"
        ixz="-2e-08"
        iyy="0.00039996"
        iyz="1.5e-07"
        izz="5.662e-05" />
    </inertial>
    <visual>
      <origin
        xyz="0 0 0"
        rpy="0 -1.5707963 -1.5707963" />
      <geometry>
        <mesh
          filename="../meshes/wrist_y_link.STL" />
      </geometry>
      <material
        name="">
        <color
          rgba="0.752941176470588 0.752941176470588 0.752941176470588 1" />
      </material>
    </visual>
    <collision>
      <origin
        xyz="0 0 0"
        rpy="0 -1.5707963 -1.5707963" />
      <geometry>
        <mesh
          filename="../meshes/wrist_y_link.STL" />
      </geometry>
    </collision>
  </link>
  <joint
    name="l_wrist_y_joint"
    type="revolute">
    <origin
      xyz="0 0 -0.0415"
      rpy="0 0 0" />
    <parent
      link="l_elb_z_link" />
    <child
      link="l_wrist_y_link" />
    <axis
      xyz="0 1 0" />
    <limit
      lower="-0.785"
      upper="0.785"
      effort="7"
      velocity="20" />
  </joint>
  <link
    name="l_wrist_x_link">
    <inertial>
      <origin
        xyz="0 0 0"
        rpy="0 0 0" />
      <mass
        value="0.13457416" />
      <inertia
        ixx="0.00040001"
        ixy="-0.0"
        ixz="-2e-08"
        iyy="0.00039996"
        iyz="1.5e-07"
        izz="5.662e-05" />
    </inertial>
    <visual>
      <origin
        xyz="0 0 0"
        rpy="1.5707963 0 1.5707963" />
      <geometry>
        <mesh
          filename="../meshes/wrist_x_link.STL" />
      </geometry>
      <material
        name="">
        <color
          rgba="0.752941176470588 0.752941176470588 0.752941176470588 1" />
      </material>
    </visual>
    <collision>
      <origin
        xyz="0 0 0"
        rpy="1.5707963 0 1.5707963" />
      <geometry>
        <mesh
          filename="../meshes/wrist_x_link.STL" />
      </geometry>
    </collision>
  </link>
  <joint
    name="l_wrist_x_joint"
    type="revolute">
    <origin
      xyz="0 0 -0.059"
      rpy="0 0 0" />
    <parent
      link="l_wrist_y_link" />
    <child
      link="l_wrist_x_link" />
    <axis
      xyz="1 0 0" />
    <limit
      lower="-0.785"
      upper="0.785"
      effort="7"
      velocity="20" />
  </joint>
  <link
    name="r_shld_y_link">
    <inertial>
      <origin
        xyz="0.00068297 0.00449372 -2.22e-06"
        rpy="0 0 0" />
      <mass
        value="0.53804971" />
      <inertia
        ixx="0.00030648"
        ixy="-4.03e-06"
        ixz="-2e-08"
        iyy="0.00029153"
        iyz="1e-07"
        izz="0.00032312" />
    </inertial>
    <visual>
      <origin
        xyz="0 0 0"
        rpy="0 0 0" />
      <geometry>
        <mesh
          filename="../meshes/r_shld_y_link.STL" />
      </geometry>
      <material
        name="">
        <color
          rgba="1 1 1 1" />
      </material>
    </visual>
    <collision>
      <origin
        xyz="0 0 0"
        rpy="0 0 0" />
      <geometry>
        <mesh
          filename="../meshes/r_shld_y_link.STL" />
      </geometry>
    </collision>
  </link>
  <joint
    name="r_shld_y_joint"
    type="revolute">
    <origin
      xyz="0 -0.21705 0.09205"
      rpy="0 0 0" />
    <parent
      link="base_link" />
    <child
      link="r_shld_y_link" />
    <axis
      xyz="0 1 0" />
    <limit
      lower="-2"
      upper="2"
      effort="27"
      velocity="20" />
  </joint>
  <link
    name="r_shld_x_link">
    <inertial>
      <origin
        xyz="2.047e-05 -5.316e-05 -0.06162654"
        rpy="0 0 0" />
      <mass
        value="0.48847489" />
      <inertia
        ixx="0.00027194"
        ixy="4e-08"
        ixz="5.4e-07"
        iyy="0.00033709"
        iyz="5.4e-07"
        izz="0.0002884" />
    </inertial>
    <visual>
      <origin
        xyz="0 0 0"
        rpy="0 0 0" />
      <geometry>
        <mesh
          filename="../meshes/r_shld_x_link.STL" />
      </geometry>
      <material
        name="">
        <color
          rgba="0.752941176470588 0.752941176470588 0.752941176470588 1" />
      </material>
    </visual>
    <collision>
      <origin
        xyz="0 0 0"
        rpy="0 0 0" />
      <geometry>
        <mesh
          filename="../meshes/r_shld_x_link.STL" />
      </geometry>
    </collision>
  </link>
  <joint
    name="r_shld_x_joint"
    type="revolute">
    <origin
      xyz="0 0 0"
      rpy="0 0 0" />
    <parent
      link="r_shld_y_link" />
    <child
      link="r_shld_x_link" />
    <axis
      xyz="1 0 0" />
    <limit
      lower="-1.57"
      upper="0.5"
      effort="27"
      velocity="20" />
  </joint>
  <link
    name="r_shld_z_link">
    <inertial>
      <origin
        xyz="-4.164e-05 -0.00022669 -0.2212782"
        rpy="0 0 0" />
      <mass
        value="0.59309528" />
      <inertia
        ixx="0.00136573"
        ixy="5.3e-07"
        ixz="1e-08"
        iyy="0.00133989"
        iyz="-1.22e-06"
        izz="0.00030342" />
    </inertial>
    <visual>
      <origin
        xyz="0 0 0"
        rpy="0 0 0" />
      <geometry>
        <mesh
          filename="../meshes/r_shld_z_link.STL" />
      </geometry>
      <material
        name="">
        <color
          rgba="0.752941176470588 0.752941176470588 0.752941176470588 1" />
      </material>
    </visual>
    <collision>
      <origin
        xyz="0 0 0"
        rpy="0 0 0" />
      <geometry>
        <mesh
          filename="../meshes/r_shld_z_link.STL" />
      </geometry>
    </collision>
  </link>
  <joint
    name="r_shld_z_joint"
    type="revolute">
    <origin
      xyz="0 0 0"
      rpy="0 0 0" />
    <parent
      link="r_shld_x_link" />
    <child
      link="r_shld_z_link" />
    <axis
      xyz="0 0 1" />
    <limit
      lower="-1.57"
      upper="1.57"
      effort="7"
      velocity="20" />
  </joint>
  <link
    name="r_elb_y_link">
    <inertial>
      <origin
        xyz="-5.192e-05 -1.999e-05 -0.08561189"
        rpy="0 0 0" />
      <mass
        value="0.50005725" />
      <inertia
        ixx="0.00043713"
        ixy="-4e-08"
        ixz="4.9e-07"
        iyy="0.00036043"
        iyz="-6.3e-07"
        izz="0.00030266" />
    </inertial>
    <visual>
      <origin
        xyz="0 0 0"
        rpy="0 0 0" />
      <geometry>
        <mesh
          filename="../meshes/r_elb_y_link.STL" />
      </geometry>
      <material
        name="">
        <color
          rgba="0.752941176470588 0.752941176470588 0.752941176470588 1" />
      </material>
    </visual>
    <collision>
      <origin
        xyz="0 0 0"
        rpy="0 0 0" />
      <geometry>
        <mesh
          filename="../meshes/r_elb_y_link.STL" />
      </geometry>
    </collision>
  </link>
  <joint
    name="r_elb_y_joint"
    type="revolute">
    <origin
      xyz="0 0 -0.24"
      rpy="0 0 0" />
    <parent
      link="r_shld_z_link" />
    <child
      link="r_elb_y_link" />
    <axis
      xyz="0 1 0" />
    <limit
      lower="-2.355"
      upper="0.5"
      effort="27"
      velocity="20" />
  </joint>
  <link
    name="r_elb_z_link">
    <inertial>
      <origin
        xyz="0 0 0"
        rpy="0 0 0" />
      <mass
        value="0.13457416" />
      <inertia
        ixx="0.00040001"
        ixy="-0.0"
        ixz="-2e-08"
        iyy="0.00039996"
        iyz="1.5e-07"
        izz="5.662e-05" />
    </inertial>
    <visual>
      <origin
        xyz="0 0 0"
        rpy="3.1415926 0 1.5707963" />
      <geometry>
        <mesh
          filename="../meshes/elb_z_link.STL" />
      </geometry>
      <material
        name="">
        <color
          rgba="0.752941176470588 0.752941176470588 0.752941176470588 1" />
      </material>
    </visual>
    <collision>
      <origin
        xyz="0 0 0"
        rpy="3.1415926 0 1.5707963" />
      <geometry>
        <mesh
          filename="../meshes/elb_z_link.STL" />
      </geometry>
    </collision>
  </link>
  <joint
    name="r_elb_z_joint"
    type="revolute">
    <origin
      xyz="0 0 -0.12"
      rpy="0 0 0" />
    <parent
      link="r_elb_y_link" />
    <child
      link="r_elb_z_link" />
    <axis
      xyz="0 0 1" />
    <limit
      lower="-0.785"
      upper="0.785"
      effort="7"
      velocity="20" />
  </joint>
  <link
    name="r_wrist_y_link">
    <inertial>
      <origin
        xyz="0 0 0"
        rpy="0 0 0" />
      <mass
        value="0.13457416" />
      <inertia
        ixx="0.00040001"
        ixy="-0.0"
        ixz="-2e-08"
        iyy="0.00039996"
        iyz="1.5e-07"
        izz="5.662e-05" />
    </inertial>
    <visual>
      <origin
        xyz="0 0 0"
        rpy="0 -1.5707963 -1.5707963" />
      <geometry>
        <mesh
          filename="../meshes/wrist_y_link.STL" />
      </geometry>
      <material
        name="">
        <color
          rgba="0.752941176470588 0.752941176470588 0.752941176470588 1" />
      </material>
    </visual>
    <collision>
      <origin
        xyz="0 0 0"
        rpy="0 -1.5707963 -1.5707963" />
      <geometry>
        <mesh
          filename="../meshes/wrist_y_link.STL" />
      </geometry>
    </collision>
  </link>
  <joint
    name="r_wrist_y_joint"
    type="revolute">
    <origin
      xyz="0 0 -0.0415"
      rpy="0 0 0" />
    <parent
      link="r_elb_z_link" />
    <child
      link="r_wrist_y_link" />
    <axis
      xyz="0 1 0" />
    <limit
      lower="-0.785"
      upper="0.785"
      effort="7"
      velocity="20" />
  </joint>
  <link
    name="r_wrist_x_link">
    <inertial>
      <origin
        xyz="0 0 0"
        rpy="0 0 0" />
      <mass
        value="0.13457416" />
      <inertia
        ixx="0.00040001"
        ixy="-0.0"
        ixz="-2e-08"
        iyy="0.00039996"
        iyz="1.5e-07"
        izz="5.662e-05" />
    </inertial>
    <visual>
      <origin
        xyz="0 0 0"
        rpy="1.5707963 0 1.5707963" />
      <geometry>
        <mesh
          filename="../meshes/wrist_x_link.STL" />
      </geometry>
      <material
        name="">
        <color
          rgba="0.752941176470588 0.752941176470588 0.752941176470588 1" />
      </material>
    </visual>
    <collision>
      <origin
        xyz="0 0 0"
        rpy="1.5707963 0 1.5707963" />
      <geometry>
        <mesh
          filename="../meshes/wrist_x_link.STL" />
      </geometry>
    </collision>
  </link>
  <joint
    name="r_wrist_x_joint"
    type="revolute">
    <origin
      xyz="0 0 -0.059"
      rpy="0 0 0" />
    <parent
      link="r_wrist_y_link" />
    <child
      link="r_wrist_x_link" />
    <axis
      xyz="1 0 0" />
    <limit
      lower="-0.785"
      upper="0.785"
      effort="7"
      velocity="20" />
  </joint>

  <link name="world">
  </link>
  <joint name="world_joint" type="floating">
     <parent link="world"/>
     <child link="base_link"/>
  </joint>
</robot>