<mujoco model="elf2">
  <compiler angle="radian" autolimits="true"/>
  <default/>
  <asset>
    <mesh name="base_link" file="base_link.STL"/>
    <mesh name="l_shld_y_link" file="l_shld_y_link.STL"/>
    <mesh name="l_shld_x_link" file="l_shld_x_link.STL"/>
    <mesh name="l_shld_z_link" file="l_shld_z_link.STL"/>
    <mesh name="l_elb_y_link" file="l_elb_y_link.STL"/>
    <mesh name="elb_z_link" file="elb_z_link.STL"/>
    <mesh name="wrist_y_link" file="wrist_y_link.STL"/>
    <mesh name="wrist_x_link" file="wrist_x_link.STL"/>
    <mesh name="r_shld_y_link" file="r_shld_y_link.STL"/>
    <mesh name="r_shld_x_link" file="r_shld_x_link.STL"/>
    <mesh name="r_shld_z_link" file="r_shld_z_link.STL"/>
    <mesh name="r_elb_y_link" file="r_elb_y_link.STL"/>
  </asset>
  <worldbody>
    <body name="base_link" pos="0 0 0" gravcomp="0">
      <inertial pos="-0.002719 0.001928 0.003917" quat="0.99998 0.000694877 0.00586675 -0.00203064" mass="8.94844" diaginertia="0.187477 0.142271 0.0695066"/>
      <joint name="world_joint" type="free"/>
      <geom type="mesh" rgba="0.75294 0.75294 0.75294 1" mesh="base_link"/>
      <body name="l_shld_y_link" pos="0 0.21705 0.09205" gravcomp="0">
        <inertial pos="0.00068297 -0.00449372 2.22e-06" quat="0.435933 0.557654 -0.43314 0.558009" mass="0.53805" diaginertia="0.00032312 0.000307497 0.000290513"/>
        <joint name="l_shld_y_joint" pos="0 0 0" axis="0 1 0" range="-2 2"/>
        <geom type="mesh" rgba="0.752941 0.752941 0.752941 1" mesh="l_shld_y_link"/>
        <body name="l_shld_x_link" pos="0 0 0" gravcomp="0">
          <inertial pos="-2.047e-05 5.316e-05 -0.0616265" quat="0.511019 0.489093 0.494385 0.505204" mass="0.488475" diaginertia="0.000337096 0.000288412 0.000271922"/>
          <joint name="l_shld_x_joint" pos="0 0 0" axis="1 0 0" range="-0.5 1.57"/>
          <geom type="mesh" rgba="0.752941 0.752941 0.752941 1" mesh="l_shld_x_link"/>
          <body name="l_shld_z_link" pos="0 0 0" gravcomp="0">
            <inertial pos="4.164e-05 0.00022669 -0.221278" quat="0.999947 0.000588453 -1.03341e-06 0.0102498" mass="0.593095" diaginertia="0.00136574 0.00133988 0.000303419"/>
            <joint name="l_shld_z_joint" pos="0 0 0" axis="0 0 1" range="-1.57 1.57"/>
            <geom type="mesh" rgba="0.752941 0.752941 0.752941 1" mesh="l_shld_z_link"/>
            <body name="l_elb_y_link" pos="0 0 -0.24" gravcomp="0">
              <inertial pos="5.192e-05 1.999e-05 -0.0856119" quat="0.999983 0.00544979 0.0018217 -0.000285656" mass="0.500057" diaginertia="0.000437132 0.000360437 0.000302651"/>
              <joint name="l_elb_y_joint" pos="0 0 0" axis="0 1 0" range="-2.355 0.5"/>
              <geom type="mesh" rgba="0.752941 0.752941 0.752941 1" mesh="l_elb_y_link"/>
              <body name="l_elb_z_link" pos="0 0 -0.12" gravcomp="0">
                <inertial pos="0 0 0" quat="1 0.00021844 2.91405e-05 -8.74832e-05" mass="0.134574" diaginertia="0.00040001 0.00039996 5.66199e-05"/>
                <joint name="l_elb_z_joint" pos="0 0 0" axis="0 0 1" range="-0.785 0.785"/>
                <geom quat="1.89469e-08 0.707107 0.707107 1.89469e-08" type="mesh" rgba="0.752941 0.752941 0.752941 1" mesh="elb_z_link"/>
                <body name="l_wrist_y_link" pos="0 0 -0.0415" gravcomp="0">
                  <inertial pos="0 0 0" quat="1 0.00021844 2.91405e-05 -8.74832e-05" mass="0.134574" diaginertia="0.00040001 0.00039996 5.66199e-05"/>
                  <joint name="l_wrist_y_joint" pos="0 0 0" axis="0 1 0" range="-0.785 0.785"/>
                  <geom quat="0.5 -0.5 -0.5 -0.5" type="mesh" rgba="0.752941 0.752941 0.752941 1" mesh="wrist_y_link"/>
                  <body name="l_wrist_x_link" pos="0 0 -0.059" gravcomp="0">
                    <inertial pos="0 0 0" quat="1 0.00021844 2.91405e-05 -8.74832e-05" mass="0.134574" diaginertia="0.00040001 0.00039996 5.66199e-05"/>
                    <joint name="l_wrist_x_joint" pos="0 0 0" axis="1 0 0" range="-0.785 0.785"/>
                    <geom quat="0.5 0.5 0.5 0.5" type="mesh" rgba="0.752941 0.752941 0.752941 1" mesh="wrist_x_link"/>
                  </body>
                </body>
              </body>
            </body>
          </body>
        </body>
      </body>
      <body name="r_shld_y_link" pos="0 -0.21705 0.09205" gravcomp="0">
        <inertial pos="0.00068297 0.00449372 -2.22e-06" quat="0.558009 0.43314 -0.557654 0.435933" mass="0.53805" diaginertia="0.00032312 0.000307497 0.000290513"/>
        <joint name="r_shld_y_joint" pos="0 0 0" axis="0 1 0" range="-2 2"/>
        <geom type="mesh" rgba="1 1 1 1" mesh="r_shld_y_link"/>
        <body name="r_shld_x_link" pos="0 0 0" gravcomp="0">
          <inertial pos="2.047e-05 -5.316e-05 -0.0616265" quat="0.489093 0.511019 0.505204 0.494385" mass="0.488475" diaginertia="0.000337096 0.000288412 0.000271922"/>
          <joint name="r_shld_x_joint" pos="0 0 0" axis="1 0 0" range="-1.57 0.5"/>
          <geom type="mesh" rgba="0.752941 0.752941 0.752941 1" mesh="r_shld_x_link"/>
          <body name="r_shld_z_link" pos="0 0 0" gravcomp="0">
            <inertial pos="-4.164e-05 -0.00022669 -0.221278" quat="0.999947 -0.000588453 1.03341e-06 0.0102498" mass="0.593095" diaginertia="0.00136574 0.00133988 0.000303419"/>
            <joint name="r_shld_z_joint" pos="0 0 0" axis="0 0 1" range="-1.57 1.57"/>
            <geom type="mesh" rgba="0.752941 0.752941 0.752941 1" mesh="r_shld_z_link"/>
            <body name="r_elb_y_link" pos="0 0 -0.24" gravcomp="0">
              <inertial pos="-5.192e-05 -1.999e-05 -0.0856119" quat="0.999983 -0.00544979 -0.0018217 -0.000285656" mass="0.500057" diaginertia="0.000437132 0.000360437 0.000302651"/>
              <joint name="r_elb_y_joint" pos="0 0 0" axis="0 1 0" range="-2.355 0.5"/>
              <geom type="mesh" rgba="0.752941 0.752941 0.752941 1" mesh="r_elb_y_link"/>
              <body name="r_elb_z_link" pos="0 0 -0.12" gravcomp="0">
                <inertial pos="0 0 0" quat="1 0.00021844 2.91405e-05 -8.74832e-05" mass="0.134574" diaginertia="0.00040001 0.00039996 5.66199e-05"/>
                <joint name="r_elb_z_joint" pos="0 0 0" axis="0 0 1" range="-0.785 0.785"/>
                <geom quat="1.89469e-08 0.707107 0.707107 1.89469e-08" type="mesh" rgba="0.752941 0.752941 0.752941 1" mesh="elb_z_link"/>
                <body name="r_wrist_y_link" pos="0 0 -0.0415" gravcomp="0">
                  <inertial pos="0 0 0" quat="1 0.00021844 2.91405e-05 -8.74832e-05" mass="0.134574" diaginertia="0.00040001 0.00039996 5.66199e-05"/>
                  <joint name="r_wrist_y_joint" pos="0 0 0" axis="0 1 0" range="-0.785 0.785"/>
                  <geom quat="0.5 -0.5 -0.5 -0.5" type="mesh" rgba="0.752941 0.752941 0.752941 1" mesh="wrist_y_link"/>
                  <body name="r_wrist_x_link" pos="0 0 -0.059" gravcomp="0">
                    <inertial pos="0 0 0" quat="1 0.00021844 2.91405e-05 -8.74832e-05" mass="0.134574" diaginertia="0.00040001 0.00039996 5.66199e-05"/>
                    <joint name="r_wrist_x_joint" pos="0 0 0" axis="1 0 0" range="-0.785 0.785"/>
                    <geom quat="0.5 0.5 0.5 0.5" type="mesh" rgba="0.752941 0.752941 0.752941 1" mesh="wrist_x_link"/>
                  </body>
                </body>
              </body>
            </body>
          </body>
        </body>
      </body>
    </body>
  </worldbody>
</mujoco>
